Workbook

Sheet orders_raw
A1: order_id | B1: order_date | C1: customer_id | D1: customer_name | E1: email | F1: phone | G1: region | H1: sales_channel | I1: status | J1: sku | K1: product_name | L1: category | M1: unit_price_gbp | N1: quantity | O1: total_price | P1: currency | Q1: shipping_method | R1: payment_type | S1: notes
A2: ORD-100718 | B2: 29-Mar-2024 | C2: CUST-5524 | D2: Tara Walker | E2: tara.walker@example.com | F2: 07992 178 353 | G2: Poland | H2: In-Store | I2: aCncelled | J2: SKU-1125 | K2: Docking Station Pro | L2: ACCESSORIES | M2: 587.78 | N2: 2 | O2: €1,224.22 | P2: EUR | Q2: Next Day | R2: Card
A3: ORD-100720 | B3: 06.02.2023 | C3: CUST-5367 | D3: NINA SMITH | E3: Nina.Smith@Gmail.Com | F3: +44 718 938 4674 | G3: Spain | H3: Marketplace | I3: Shipped | J3: SKU-1050 | K3: Ultrabook 14 | L3: tSorage | N3: 2 | O3: $828,41 | P3: USD | Q3: Standard | R3: PayPal | S3: gift
A4: ORD-100128 | B4: 22/05/2023 20:20 | C4: CUST-5554 | D4: Igor Brown | E4: Igor.Brown@Shop.Io | F4: +44 623 652 7366 | G4: France | H4: Mobile App | I4: Paid | J4: SKU-1148 | K4: Portable HDD 2TB | L4: Computers | M4: 179.29 | N4: 2 | O4: GBP 373.42 | P4: GBP | Q4: Express | R4: PayPal | S4: urgent
A5: ORD-100513 | B5: 31-Aug-2024 | C5: CUST-5111 | D5: Marek Khan | E5: Marek.Khan@Company.Co.Uk | G5: UK | H5: Marketplace | I5: Refunded | J5: SKU-1139 | K5: Nvme Ssd 2Tb | L5: Smart Hoem | M5: 1704.12 | N5: 2 | O5: GBP 3,494.77 | P5: GBP | Q5: Next Day | R5: Cash | S5: delayed
A6: ORD-100653 | B6: 2025/04/03 | C6: CUST-5082 | D6: Qi Smith | E6: qi.smith@gmail.com | F6: +44 711 862 5723 | G6: Ireland | H6: In-Stroe | I6: Refunded | J6: SKU-1119 | K6: LED Light Strip | L6: Audio | M6: 417.04 | N6: 1 | O6: zł418.27 | P6: PLN | Q6: PICKUP | R6: Crad
A7: ORD-100336 | B7: 2025/09/25 | C7: CUST-5621 | D7: Sam Lopez | E7: sam.lopez@gmail.com | G7: Ireland | H7: Marketplace | I7: Refunded | J7: SKU-1000 | K7: Router XA5400 | L7: Audoi | M7: 1448.91 | N7: 1 | O7: EUR 1,436.62 | P7: EUR | Q7: Express | R7: Cash
A8: ORD-100898 | B8: Mar 01, 2023 08:59 | C8: CUST-5377 | D8: Gabe Garcia | E8: gabe.garcia@example.com | F8: +1-660-253-6456 | G8: UK | H8: Web | I8: Cancelled | J8: SKU-1019 | K8: LED Light Strip | L8: Computers | N8: 5 | O8: $2,894.38 | P8: USD | Q8: Standard | R8: GIFT CARD | S8: urgent
A9: ORD-100355 | B9: 2025/06/11 | C9: CUST-5077 | D9: Tara Khan | E9: tara.khan@company.co.uk | F9: +1-257-200-4796 | G9: Ireland | H9: Mobile App | I9: Refunded | J9: SKU-1048 | K9: External SSD 1BT | L9: NETWORKING | N9: 2 | O9: USD 1,966.67 | P9: USD | Q9: NEXT DAY | R9: Bank Transfer | S9: VIP
A10: ORD-100168 | B10: 45783 | C10: CUST-5101 | D10: Omar Khan | E10: Omar.Khan@Shop.Io | G10: Spain | H10: In-Store | I10: Shipped | J10: SKU-1022 | K10: Smart Plug 2-Pack | L10: Computers | N10: 2 | O10: zł1,057.28 | P10: PLN | Q10: Pickup | R10: Gift Card | S10: gift
A11: ORD-100597 | B11: 2025-09-27 | C11: CUST-5010 | D11: Hanna Kowalski | E11: hanna.kowalski@company.co.uk | F11: 4+4 993 638 5784 | G11: USA | H11: Web | I11: eRfunded | J11: SKU-1069 | K11: Portable HDD 2TB | L11: A udio | M11: 750.84 | N11: 1 | O11: GBP 784.00 | P11: GBP | Q11: Pcikup | R11: Gift Card | S11: VIP
A12: ORD-100101 | B12: 2025/02/25 | C12: CUST-5288 | D12: Lia Taylor | E12: Lia.Taylor@Example.Com | F12: +1-353-409-3163 | G12: Usa | H12: Web | I12: Refunded | J12: SKU-1039 | K12: LED Light Strip | L12: Monitors | M12: 1401.64 | N12: 2 | O12: $2,775.90 | P12: USD | Q12: Standard | R12: PayPal
A13: ORD-100977 | B13: 2025-02-28 | C13: CUST-5072 | D13: Wiktor Young | E13: witkor.young@yahoo.com | F13: +44 442 197 9030 | G13: France | H13: Marketplace | I13: Paid | J13: SKU-1024 | K13: 4 K Monitor 32 | L13: Accessories | M13: 1503.67 | N13: 3 | O13: EUR 4,648.50 | P13: EUR | Q13: Next Day | R13: Card | S13: VIP
A14: ORD-100457 | B14: 09-Jun-2024 | C14: CUST-5670 | D14: Ken Novak | E14: ken.novak@company.co.uk | F14: +44 434 357 1644 | G14: Spain | H14: Web | I14: Refunded | J14: SKU-1080 | K14: Bluetooth Speaker | L14: Monitors | M14: 856.9 | N14: 3 | O14: £2692,3 | P14: GBP | Q14: Pickup | R14: Bank Transfer | S14: VIP
A15: ORD-100414 | B15: 04/04/2024 18:09 | C15: CUST-5056 | D15: Zack Muller | E15: Zack.Muller@Shop.Io | F15: +1-882-256-7084 | G15: USA | H15: In-Store | I15: Refunded | J15: SKU-1130 | K15: Bluetooth Speaker | L15: COMPUETRS | N15: 1 | O15: GBP 1,674.83 | P15: GBP | Q15: Pickup | R15: PayPal | S15: delayed
A16: ORD-100264 | B16: 26-Feb-2024 | C16: CUST-5652 | D16: Omar Brown | E16: omar.brown@company.co.uk | G16: Spain | H16: Mobile App | I16: CANCELLED | J16: SKU-1076 | K16: Gaming Laptop 15 | L16: Audio | M16: 46.08 | N16: 1 | O16: $45,54 | P16: USD | Q16: Pickup | R16: Gfit Card | S16: urgent
A17: ORD-100848 | B17: 07/13/2025 | C17: CUST-5507 | D17: Vlad Williams | E17: vlad.williams@gmail.com | F17: +1-667-478-2689 | G17: UK | H17: Web | I17: Paid | J17: SKU-1108 | K17: SMART PLUG 2-PACK | L17: Audio | M17: 906.04 | N17: 2 | O17: USD 1,888.10 | P17: USD | Q17: Pickup | R17: aCrd
A18: ORD-100901 | B18: 25.12.2024 22:49 | C18: CUST-5289 | D18: PAULA MARTINEZ | E18: PAULA.MARTINEZ@EXAMPLE.COM | F18: +44 395 454 0136 | G18: Ireland | H18: In-Store | I18: Refunded | J18: SKU-1034 | K18: Wireless Mouse | L18: ACCESSORIES | M18: 768.63 | N18: 1 | O18: PLN 763.17 | P18: PLN | Q18: EXPRESS | R18: Bank Tarnsfer
A19: ORD-100046 | B19: 08.10.2023 | C19: CUST-5412 | D19: Ken Kowalczyk | E19: ken.kowlaczyk@shop.io | F19: +44 769 186 7502 | G19: France | H19: Marketplace | I19: Paid | J19: SKU-1093 | K19: Gaming Chair | L19: Storage | M19: 1497.04 | N19: 3 | O19: $4,347.91 | P19: USD | Q19: Picku p | R19: Bank Transfer
A20: ORD-100902 | B20: 11-Jul-2024 | C20: CUST-5118 | D20: Daria King | E20: daria.king@yahoo.com | F20: +1-440-780-7545 | G20: Ireland | H20: Web | I20: Paid | J20: SKU-1047 | K20: LED Light Strip | L20: Audio | N20: 1 | O20: $403,47 | P20: USD | Q20: Pickup | R20: Paypal | S20: VIP
A21: ORD-100881 | B21: 07/17/2023 20:01 | C21: CUST-5037 | D21: Omar Young | E21: omar.young@company.co.uk | F21: +1-468-684-6697 | G21: UK | H21: Marketplace | I21: Padi | J21: SKU-1060 | K21: Noise Cancelling Headphones | L21: AUDIO | N21: 1 | O21: USD 468.40 | P21: USD | Q21: Pickup | R21: PayPal | S21: urgent
A22: ORD-101119 | B22: 29-May-2023 | C22: CUST-5565 | D22: Yara Rossi | E22: yara.rossi@company.co.uk | F22: +1-605-656-6749 | G22: Poland | H22: Marketplace | I22: Refunded | J22: SKU-1103 | K22: External SSD 1TB | L22: Storaeg | N22: 1 | O22: USD 25.92 | P22: Usd | Q22: Next Day | R22: PayPal | S22: urgent
A23: ORD-100432 | B23: 45704 | C23: CUST-5334 | D23: Hanna Dubois | F23: +1-505-572-3052 | G23: UK | H23: Web | I23: Shipped | J23: SKU-1005 | K23: NVMe SSD 2TB | L23: COMPUTERS | M23: 614.07 | N23: 3 | O23: EUR 1,773.39 | P23: EUR | Q23: Standard | R23: Card
A24: ORD-100454 | B24: 28-Dec-2024 | C24: CUST-5345 | D24: Bella Davis | E24: Bella.Davis@Yahoo.Com | F24: +1-404-983-6248 | G24: Spain | H24: IN-STORE | I24: Refunded | J24: SKU-1035 | K24: DOCKING STATION PRO | L24: Storage | M24: 1559.25 | N24: 1 | O24: £1,547.35 | P24: GBP | Q24: Standard | R24: Bank Transfer | S24: urgent
A25: ORD-101063 | B25: 28-Aug-2025 | C25: CUST-5678 | D25: Yara Walker | F25: +44 583 359 1842 | G25: Usa | H25: Marketplace | I25: Shipped | J25: SKU-1012 | K25: Wireless Mouse | L25: Accessories | M25: 1094.59 | N25: 5 | O25: USD 5,283.39 | P25: USD | Q25: Pickup | R25: PayPal | S25: VIP
A26: ORD-100466 | B26: 03/04/2024 17:51 | C26: CUST-5407 | D26: Omar Taylor | E26: omar.taylor@company.co.uk | F26: +44 914 229 6422 | G26: France | H26: Mobile App | I26: Pendnig | J26: SKU-1077 | K26: External SSD 1TB | L26: Accessories | N26: 1 | O26: zł9.56 | P26: PLN | Q26: Standard | R26: Bank Transfer
A27: ORD-100009 | B27: 30-Aug-2023 | C27: CUST-5599 | D27: Marek Smith | E27: Marek.Smith@Outloo.kCom | G27: Spain | H27: Mobile App | I27: Pending | J27: SKU-1104 | K27: Docking Station Pro | L27: Storage | M27: 709.89 | O27: £718.45 | P27: GBP | Q27: NextD ay | R27: PayPal | S27: delayed
A28: ORD-100571 | B28: Sep 27, 2025 | C28: CUST-5287 | D28: PAULA NOVAK | E28: paula.novak@gmail.com | F28: 07535 426 253 | G28: Poland | H28: Marketplace | I28: Paid | J28: SKU-1060 | K28: Noise Cancelling Headphones | L28: AUDIO | M28: 680.14 | N28: 1 | O28: USD 691.78 | P28: USD | Q28: Pickup | R28: PayPal | S28: VIP
A29: ORD-100534 | B29: 01/24/2025 | C29: CUST-5569 | D29: ETHAN KOWALSKI | E29: ethan.kowalski@example.com | F29: +1-736-338-1390 | G29: Poland | H29: Marketplace | I29: Cancelled | J29: SKU-1089 | K29: Portable HDD 2TB | L29: Smart Home | N29: 2 | O29: $673,86 | P29: USD | Q29: Epxress | R29: PayPal | S29: urgent
A30: ORD-100113 | B30: Jan 12, 2023 06:29 | C30: CUST-5136 | D30: Adam Kowalczyk | E30: Adam.Kowalczyk@Outlook.Com | F30: +1-368-779-5228 | G30: Italy | H30: Marketplace | I30: PENDING | J30: SKU-1070 | K30: Ultraobok 14 | L30: Audio | N30: 2 | O30: GBP 1,006.25 | P30: GBP | Q30: Pickup | R30: Card | S30: gift
A31: ORD-100685 | B31: 07/04/2025 | C31: CUST-5187 | D31: Ethan Kowalski | E31: Ethan.Kowalski@Example.Com | F31: +44 167 297 1510 | G31: Franc e | H31: Mobile App | I31: Paid | J31: SKU-1024 | K31: 4 K Monitor 32 | L31: Accessories | M31: 1309.01 | N31: 1 | O31: EUR 1,372.09 | P31: EUR | Q31: iPckup | R31: Cash | S31: gift
A32: ORD-100526 | B32: May 08, 2025 | C32: CUST-5313 | D32: ACRLOS DUBOIS | E32: carlos.dubois@gmail.com | F32: +44 129 997 2553 | G32: ITALY | H32: Mobiel App | I32: Cancellde | J32: SKU-1115 | K32: 27in Monitor | L32: Storage | N32: 2 | O32: GBP 1,887.10 | P32: GBP | Q32: Pickup | R32: CARD | S32: VIP
A33: ORD-101011 | B33: 07/19/2024 | C33: CUST-5119 | D33: Ehtan Taylor | E33: ethan.taylor@outlook.com | G33: UK | H33: Mobile App | I33: Pending | J33: SKU-1031 | K33: USB-C Hub 7in1 | L33: Sotrage | M33: 1660.79 | N33: 1 | O33: USD 1,663.84 | P33: USD | Q33: Next Day | R33: Cash
A34: ORD-101147 | B34: 01/01/2025 | C34: CUST-5515 | D34: Sam Young | E34: sam.young@yahoo.com | G34: France | H34: Web | I34: Shipped | J34: SKU-1061 | K34: 27INM ONITOR | L34: Monitors | N34: 3 | O34: zł4,133.34 | P34: PLN | Q34: STANDARD | R34: GIFT CARD
A35: ORD-100587 | B35: 45753 11:38 | C35: CUST-5125 | D35: Lia Davis | E35: LIA.DAVIS@YAHOO.COM | F35: +44 272 275 2968 | G35: France | H35: Mobile App | I35: Refunded | J35: SKU-1129 | K35: Microphone USB | L35: COMPUTERS | M35: 1383.78 | N35: 5 | O35: zł7,064.26 | P35: PLN | Q35: PICKUP | R35: PayPal | S35: VIP
A36: ORD-100141 | B36: 2025/03/26 | C36: CUST-5204 | D36: Zack Brown | E36: ZACK.BROWN@YAHOO.COM | F36: +44 582 74 15155 | G36: USA | H36: In-Store | I36: Shipped | J36: SKU-1080 | K36: Bluetooth Speaker | L36: Monitors | O36: GBP 1,492.86 | P36: GBP | Q36: Pickup | R36: Card
A37: ORD-100835 | B37: 45092 | C37: CUST-5504 | D37: Qi Nowak | E37: qi.nowak@yahoo.com | F37: +44 483 783 2104 | G37: Spain | H37: In-Store | I37: Pending | J37: SKU-1105 | K37: Webcam 1080p | L37: Computers | N37: 5 | O37: EUR 8,282.75 | P37: EUR | Q37: Express | R37: Cash | S37: delayed
A38: ORD-100350 | B38: 25-Nov-2023 | C38: CUST-5385 | D38: Sam Rodriguez | E38: SAM.RODRIGUEZ@SHOP.IO | G38: USA | H38: Mobile App | I38: Refunded | J38: SKU-1004 | K38: Gaming Laptop 15 | L38: Accessories | M38: 571.4 | N38: 5 | O38: USD 2,716.52 | P38: USD | Q38: Pickup | R38: PAYPAL | S38: VIP
A39: ORD-100758 | B39: 45116 | C39: CUST-5085 | D39: Xenia Lopze | E39: xenia.lopez@yahoo.com | F39: +44 330 641 1288 | G39: Germany | H39: MOBILE APP | I39: Paid | J39: SKU-1097 | K39: Smartphone Case | L39: Netwroking | M39: 759.26 | N39: 2 | O39: PLN 1,535.25 | P39: PLN | Q39: Pickup | R39: GIFT CARD
A40: ORD-100894 | B40: 19.11.2023 | C40: CUST-5326 | D40: ADAM IWLLIAMS | E40: adam.wililams@shop.io | F40: +44 354 661 1215 | G40: USA | H40: Marketplace | I40: Shipped | J40: SKU-1064 | K40: Docking Station Pro | L40: Accessories | M40: 1456.79 | N40: 1 | O40: zł1,508.64 | P40: PLN | Q40: Pickup | R40: CARD
...

Sheet customers_raw
A1: customer_id | B1: full_name | C1: email | D1: phone | E1: region | F1: created_at | G1: marketing_opt_in
A2: CUST-5191 | B2: Gabe Smith | C2: gabe.smith@example.com | D2: +1-762-417-3146 | E2: Italy | F2: 12/15/2023 05:03 | G2: No
A3: CUST-5682 | B3: Gabe King | C3: gabe.king@shop.io | D3: 04047 092 759 | E3: France | F3: 2024-10-23 | G3: Yes
A4: CUST-5318 | B4: Wiktor Williams | C4: wiktor.williams@example.com | D4: +44 150 027 7689 | E4: Poland | F4: 2025-09-25 | G4: no
A5: CUST-5562 | B5: Bella Dubois | C5: bella.dubois@shop.io | D5: +44 730 574 7856 | E5: USA | F5: Dec 22, 2022 20:11 | G5: No
A6: CUST-5623 | B6: JADE DAVIS | C6: jade.davis@yahoo.com | D6: +1-673-239-2500 | E6: Poland | F6: 45108 | G6: yes
A7: CUST-5399 | B7: Igor Kowalczyk | C7: igor.kowalczyk@example.com | D7: 01487 030 535 | E7: Poland | F7: 12/21/2023 | G7: No
A8: CUST-5657 | B8: Igor Young | C8: IGOR.YOUNG@YAHOO.COM | D8: +44 063 475 2008 | E8: Uk | F8: 05/16/2025
A9: CUST-5677 | B9: Jade Garcia | C9: jade.garcia@company.co.uk | D9: +1-795-856-9827 | E9: UK | F9: 45606 | G9: no
A10: CUST-5232 | B10: Ethan Taylor | C10: ethan.taylor@companyc.o.uk | D10: 05856 965 499 | E10: RFANCE | F10: 02/01/2023 | G10: No
A11: CUST-5544 | B11: Marek Novak | C11: marek.novak@yahoo.com | D11: +1-394-664-9948 | E11: Ireland | F11: 17.01.2022 | G11: Yes
A12: CUST-5435 | B12: Fiona Davis | C12: fiona.davis@company.co.uk | D12: +1-731-971-2240 | E12: Ireland | F12: 13-Mar-2025 17:45
A13: CUST-5057 | B13: Carlos Lee | C13: carlos.lee@company.co.uk | D13: 05360 848 529 | E13: UK | F13: 13-Jun-2022 12:23 | G13: Y
A14: CUST-5612 | B14: Gabe Martinez | C14: GABE.MARTINEZ@SHOP.IO | D14: +1-983-639-7989 | E14: GERMANY | F14: 2025-02-21 | G14: TRUE
A15: CUST-5670 | B15: Ken Novak | C15: ken.novak@company.co.uk | D15: +44 434 357 1644 | E15: Spain | F15: Dec 15, 2024 | G15: yes
A16: CUST-5229 | B16: NINA DAVIS | C16: nina.davis@outlook.com | D16: +44 925 750 9054 | E16: UK | F16: 2022-02-18
A17: CUST-5188 | B17: Xenia Kowalczyk | C17: xenia.kowalczyk@gmail.com | E17: Poland | F17: 2025/06/10 07:46
A18: CUST-5168 | B18: Yara Davis | C18: Yara.Davis@Example.Com | D18: +44 656 840 8328 | E18: ITALY | F18: 44998 09:58
A19: CUST-5223 | B19: IGOR BROWN | C19: igor.brown@outlook.com | D19: +1-778-262-8429 | E19: Ireland | F19: 21-Mar-2025
A20: CUST-5278 | B20: Vla dRodriguez | C20: Vlad.Rodriguez@Example.Com | D20: +1-832-202-5314 | E20: GERMANY | F20: 27/08/2022 | G20: N
A21: CUST-5351 | B21: UMA LOPEZ | C21: Uma.Lopez@Company.Co.Uk | D21: 04945 481 349 | E21: Ireland | F21: 25/04/2024 02:59 | G21: TRUE
A22: CUST-5236 | B22: Uma Lee | C22: uma.lee@gmail.ocm | E22: Spain | F22: 19.04.2025 | G22: yes
A23: CUST-5249 | B23: Yara Brown | C23: yara.brown@company.co.uk | D23: +44 865 848 6086 | E23: POLADN | F23: 02.01.2023
A24: CUST-5358 | B24: Hanna Kowalczyk | C24: hanna.kowalczyk@example.com | D24: 06746 868 344 | E24: Spain | F24: 2025-01-27 | G24: No
A25: CUST-5148 | B25: Yara Nowak | C25: yara.nowak@yahoo.com | D25: 06750 972 902 | E25: Fracne | F25: 45449 | G25: No
A26: CUST-5543 | B26: Wiktor Young | C26: wiktor.young@cmopany.co.uk | D26: +1-433-470-2895 | E26: Germany | F26: Jul 23, 2023 | G26: yes
A27: CUST-5272 | B27: Vlad Garcia | C27: vlad.garcia@outlook.com | D27: +44 131 853 4404 | E27: USA | F27: Aug 27, 2025 16:18 | G27: yes
A28: CUST-5698 | B28: Ethan Novak | C28: ethan.novak@gmail.com | D28: +1-546-331-6613 | E28: Itlay | F28: 07.10.2022 | G28: yes
A29: CUST-5417 | B29: Igor Muller | C29: igor.muller@yahoo.com | D29: 04470 275 125 | E29: France | F29: 04/04/2025 | G29: TRUE
A30: CUST-5650 | B30: Sam Novak | C30: sam.novak@gmail.com | D30: +1-890-678-7089 | E30: USA | F30: 06/03/2025 | G30: Yes
A31: CUST-5514 | B31: Jade Davis | C31: JADE.DAVIS@COMPANY.CO.UK | D31: +44 784 108 3844 | E31: Germany | F31: 2025/07/09 19:03 | G31: no
A32: CUST-5098 | B32: Zack Dubois | C32: zack.dubois@yahoo.com | D32: 02567 462 522 | E32: Spain | F32: 44656 | G32: no
A33: CUST-5061 | B33: Adam Garcia | C33: adam.garcia@outlook.com | D33: +44 136 191 8851 | E33: Ireland | F33: 2022/01/11 | G33: Yes
A34: CUST-5513 | B34: Ken Williams | C34: ken.williams@company.co.uk | D34: +44 346 831 3679 | E34: Spain | F34: 19.11.2024 | G34: yes
A35: CUST-5470 | B35: Ethan Muller | C35: ETHAN.MULLER@OUTLOOK.COM | D35: 01186 574 539 | E35: Ireland | F35: 23-Oct-2023 04:30
A36: CUST-5099 | B36: Marek King | C36: marek.king@gmail.com | D36: +44 662 605 1552 | E36: USA | F36: 03-Jan-2024 02:57 | G36: TRUE
A37: CUST-5009 | B37: Marek Davis | C37: marek.davis@gmail.com | D37: +44 094 948 0914 | E37: Uk | F37: 07/12/2024 | G37: FALSE
A38: CUST-5283 | B38: Zack Johnson | C38: zack.johnson@example.com | D38: +44 472 91 68833 | E38: Ireland | F38: 2022-07-19 | G38: yes
A39: CUST-5221 | B39: Jade Nowak | C39: JADE.NOWAK@EXAPMLE.COM | D39: 04361 416 433 | E39: Poland | F39: 03-Mar-2025 | G39: No
A40: CUST-5547 | B40: Carlos Taylor | C40: carlos.taylor@example.com | D40: +44 751 427 4575 | E40: Poland | F40: 2023-09-05 | G40: no
...

Sheet products_raw
A1: sku | B1: product_name | C1: category | D1: list_price | E1: active
A2: SKU-1000 | B2: Router XA5400 | C2: Audoi | D2: £716.33 | E2: Yes
A3: SKU-1001 | B3: 4K Monito r32 | C3: Computers | D3: 115.74 GBP | E3: NO
A4: SKU-1002 | B4: NOISE CANCELLING HEADPHONES | C4: Storage | D4: 759.83 GBP | E4: yes
A5: SKU-1003 | B5: USB-C Hub 7in1 | C5: Monitors | D5: €116.62 | E5: No
A6: SKU-1004 | B6: Gaming Laptop 15 | C6: Accessories | D6: 1,037.64 PLN | E6: No
A7: SKU-1005 | B7: NVMe SSD 2TB | C7: COMPUTERS | D7: 80.13 GBP | E7: FALSE
A8: SKU-1006 | B8: USB-C Hub 7in1 | C8: SMART HOME | D8: $177.43 | E8: TRUE
A9: SKU-1007 | B9: Led Light Strip | C9: Networking | D9: zł630.79 | E9: NO
A10: SKU-1008 | B10: NVMe SSD 2TB | C10: Accessories | D10: 307.62 PLN | E10: FALSE
A11: SKU-1009 | B11: Gaming Laptop 15 | C11: Audoi | D11: €158.45
A12: SKU-1010 | B12: Gaming Chair | C12: Storage | D12: £1,715.09 | E12: FALSE
A13: SKU-1011 | B13: LED LIGHT STRIP | C13: Accessories | D13: €350,99
A14: SKU-1012 | B14: Wireless Mouse | C14: Accessories | D14: zł1,574.18 | E14: FALSE
A15: SKU-1013 | B15: NVMe SSD 2TB | C15: Computesr | D15: €567.90 | E15: yes
A16: SKU-1014 | B16: 4K MONITOR 32 | C16: Accessories | D16: 1,366.32 USD
A17: SKU-1015 | B17: 4K Monitor 32 | C17: Smart Home | D17: 909.32 EUR | E17: No
A18: SKU-1016 | B18: Docking Station Pro | C18: COMPUTERS | D18: 646.09 GBP | E18: yes
A19: SKU-1017 | B19: Smart Plug 2-Pack | C19: Storage | D19: £154,07 | E19: yes
A20: SKU-1018 | B20: Smart Plug 2-Pack | C20: Smart Home | D20: 1,160.56 GBP | E20: NO
A21: SKU-1019 | B21: LED Light Strip | C21: Computers | D21: 728,08 GBP | E21: NO
A22: SKU-1020 | B22: Smartphone Case | C22: Computers | D22: $1,185.85 | E22: No
A23: SKU-1021 | B23: Microphone Usb | C23: Smart Home | D23: €358.50 | E23: Yes
A24: SKU-1022 | B24: Smart Plug 2-Pack | C24: Computers | D24: 1,195.16 PLN
A25: SKU-1023 | B25: Wireless oMuse | C25: Smart Home | D25: €1,439.71 | E25: Yes
A26: SKU-1024 | B26: 4 K Monitor 32 | C26: Accessories | D26: $454,55
A27: SKU-1025 | B27: Webcam 1080P | C27: Networking | D27: 505.88 PLN | E27: No
A28: SKU-1026 | B28: Portable DHD 2TB | C28: Audio | D28: zł755,36 | E28: yes
A29: SKU-1027 | B29: Smart Plug 2-Pack | C29: Audio | D29: 462.80 EUR | E29: No
A30: SKU-1028 | B30: Microphoen USB | C30: Monitors | D30: zł732.41
A31: SKU-1029 | B31: Smartphone Case | C31: Storage | D31: £926.43 | E31: No
A32: SKU-1030 | B32: Ultrabook 14 | C32: Smart Home | D32: 241.77 PLN | E32: TRUE
A33: SKU-1031 | B33: USB-C Hub 7in1 | C33: Sotrage | D33: €112,91 | E33: NO
A34: SKU-1032 | B34: External SSD 1TB | C34: Computers | D34: 30.65 PLN | E34: Yes
A35: SKU-1033 | B35: Bluetooth Speaker | C35: Audio | D35: 1,677.79 USD | E35: Yes
A36: SKU-1034 | B36: Wireless Mouse | C36: ACCESSORIES | D36: 1,321.48 EUR | E36: FALSE
A37: SKU-1035 | B37: DOCKING STATION PRO | C37: Storage | D37: €1,240.37 | E37: No
A38: SKU-1036 | B38: WIRELESS MOUSE | C38: Accessories | D38: $1,128,92 | E38: yes
A39: SKU-1037 | B39: 27in Monitor | C39: Accessories | D39: €831,96 | E39: TRUE
A40: SKU-1038 | B40: Webcam 1080P | C40: Stroage | D40: $337.30 | E40: No
...

Sheet customers_clean
A1: customer_id | B1: customer_id_flag | C1: full_name | D1: full_name_F | E1: name_token_count | F1: name_flag | G1: full_name_email | H1: email_F | I1: email | J1: email_flag | K1: phone | Q1: phone_flag | R1: region | S1: created_at | T1: Step_1 | U1: Step_2 | V1: Step_3 | W1: Step_4 | X1: Step_5 | Y1: creat_at_F
A2: CUST-5000 | B2: {=IF(COUNTIF(A:A,A2:A701)=1, "✅ Unique", "❌ Duplicate")} -> ✅ Unique | C2: Ethan King | D2: =IFERROR(__xludf.DUMMYFUNCTION("PROPER(REGEXREPLACE(TRIM(C2),""\s+"","" ""))"),"Ethan King") -> Ethan King | E2: =IFERROR(__xludf.DUMMYFUNCTION("IF(LEN(D2:D701), COUNTA(SPLIT(D2:D701,"" "")), """")"),2.0) -> 2 | F2: =IF(D2=G2,"✅","❌") -> ✅ | G2: =IFERROR(__xludf.DUMMYFUNCTION("REGEXEXTRACT(PROPER(SUBSTITUTE(TRIM(I2),""."","" "")),""^[^@]+"")"),"Ethan King") -> Ethan King | H2: =LOWER(TRIM(I2)) -> ethan.king@shop.i o | I2: ethan.king@shop.i o | J2: =IFERROR(__xludf.DUMMYFUNCTION("IF(REGEXMATCH(TRIM(I2),""^[A-Za-z0-9._%+-]+@[A-Za-z0-9.-]+\.[A-Za-z]{2,}$""),""✅ Valid"",""❌ Invalid"")"),"❌ Invalid") -> ❌ Invalid | K2: 18912177948 | L2: =IFERROR(__xludf.DUMMYFUNCTION("IF(OR(K2=""N/A"", K2=""missing"", K2=""none""), """", REGEXREPLACE( SUBSTITUTE(SUBSTITUTE(SUBSTITUTE(TO_TEXT(K2), CHAR(160),""""), UNICHAR(8239),""""), UNICHAR(8201),""""),""[+\-/(): )]"", """"))"),"18912177948") -> 18912177948 | M2: =IFERROR(__xludf.DUMMYFUNCTION("IF(L2="""","""", REGEXEXTRACT(REGEXREPLACE(L2,""x"", """"), ""[0-9]+""))"),"18912177948") -> 18912177948 | N2: =IF(LEFT(M2,1)="1", RIGHT(M2,LEN(M2)-1),M2) -> 8912177948 | O2: =IFERROR(__xludf.DUMMYFUNCTION("REGEXMATCH(TO_TEXT(N2), ""^[2-9][0-9]{9}$"")"),TRUE) -> TRUE | P2: =LEN(N2) -> 10 | Q2: =IF(AND(O2=TRUE, P2=10), "✅ VALID", "❌ INVALID") -> ✅ VALID | R2: USA | S2: 04/22/2025 | T2: =IFERROR(__xludf.DUMMYFUNCTION("IF(ISNUMBER(S2),TEXT(S2,""yyyy-MM-dd""),REGEXREPLACE(REGEXREPLACE(TO_TEXT(S2),""[^0-9a-zA-Z]+"",""-""),""[^0-9]*$"",""""))"),"04-22-2025") -> 04-22-2025 | U2: =TEXT(T2,"yyyy-MM-dd") -> 04-22-2025 | V2: 2025-04-22 | Y2: 2025-04-22
A3: CUST-5001 | B3: ✅ Unique | C3: Wiktor Muller | D3: =IFERROR(__xludf.DUMMYFUNCTION("PROPER(REGEXREPLACE(TRIM(C3),""\s+"","" ""))"),"Wiktor Muller") -> Wiktor Muller | E3: =IFERROR(__xludf.DUMMYFUNCTION("IF(LEN(D3:D701), COUNTA(SPLIT(D3:D701,"" "")), """")"),2.0) -> 2 | F3: =IF(D3=G3,"✅","❌") -> ✅ | G3: =IFERROR(__xludf.DUMMYFUNCTION("REGEXEXTRACT(PROPER(SUBSTITUTE(TRIM(I3),""."","" "")),""^[^@]+"")"),"Wiktor Muller") -> Wiktor Muller | H3: =LOWER(TRIM(I3)) -> wiktor.muller@shop.io | I3: wiktor.muller@shop.io | J3: =IFERROR(__xludf.DUMMYFUNCTION("IF(REGEXMATCH(TRIM(I3),""^[A-Za-z0-9._%+-]+@[A-Za-z0-9.-]+\.[A-Za-z]{2,}$""),""✅ Valid"",""❌ Invalid"")"),"✅ Valid") -> ✅ Valid | L3: =IFERROR(__xludf.DUMMYFUNCTION("IF(OR(K3=""N/A"", K3=""missing"", K3=""none""), """", REGEXREPLACE( SUBSTITUTE(SUBSTITUTE(SUBSTITUTE(TO_TEXT(K3), CHAR(160),""""), UNICHAR(8239),""""), UNICHAR(8201),""""),""[+\-/(): )]"", """"))"),"") | M3: =IFERROR(__xludf.DUMMYFUNCTION("IF(L3="""","""", REGEXEXTRACT(REGEXREPLACE(L3,""x"", """"), ""[0-9]+""))"),"") | N3: =IF(LEFT(M3,1)="1", RIGHT(M3,LEN(M3)-1),M3) | O3: =IFERROR(__xludf.DUMMYFUNCTION("REGEXMATCH(TO_TEXT(N3), ""^[2-9][0-9]{9}$"")"),FALSE) -> FALSE | P3: =LEN(N3) -> 0 | Q3: =IF(AND(O3=TRUE, P3=10), "✅ VALID", "❌ INVALID") -> ❌ INVALID | R3: USA | S3: 45813 | T3: =IFERROR(__xludf.DUMMYFUNCTION("IF(ISNUMBER(S3),TEXT(S3,""yyyy-MM-dd""),REGEXREPLACE(REGEXREPLACE(TO_TEXT(S3),""[^0-9a-zA-Z]+"",""-""),""[^0-9]*$"",""""))"),"2025-06-05") -> 2025-06-05 | U3: 2025-06-05 | Y3: 2025-06-05
A4: CUST-5002 | B4: ✅ Unique | C4: Lia Novak | D4: =IFERROR(__xludf.DUMMYFUNCTION("PROPER(REGEXREPLACE(TRIM(C4),""\s+"","" ""))"),"Lia Novak") -> Lia Novak | E4: =IFERROR(__xludf.DUMMYFUNCTION("IF(LEN(D4:D701), COUNTA(SPLIT(D4:D701,"" "")), """")"),2.0) -> 2 | F4: =IF(D4=G4,"✅","❌") -> ✅ | G4: =IFERROR(__xludf.DUMMYFUNCTION("REGEXEXTRACT(PROPER(SUBSTITUTE(TRIM(I4),""."","" "")),""^[^@]+"")"),"Lia Novak") -> Lia Novak | H4: =LOWER(TRIM(I4)) -> lia.novak@gmail.com | I4: lia.novak@gmail.com | J4: =IFERROR(__xludf.DUMMYFUNCTION("IF(REGEXMATCH(TRIM(I4),""^[A-Za-z0-9._%+-]+@[A-Za-z0-9.-]+\.[A-Za-z]{2,}$""),""✅ Valid"",""❌ Invalid"")"),"✅ Valid") -> ✅ Valid | K4: +441895238062 ext 644 | L4: =IFERROR(__xludf.DUMMYFUNCTION("IF(OR(K4=""N/A"", K4=""missing"", K4=""none""), """", REGEXREPLACE( SUBSTITUTE(SUBSTITUTE(SUBSTITUTE(TO_TEXT(K4), CHAR(160),""""), UNICHAR(8239),""""), UNICHAR(8201),""""),""[+\-/(): )]"", """"))"),"441895238062ext644") -> 441895238062ext644 | M4: =IFERROR(__xludf.DUMMYFUNCTION("IF(L4="""","""", REGEXEXTRACT(REGEXREPLACE(L4,""x"", """"), ""[0-9]+""))"),"441895238062") -> 441895238062 | N4: =IF(LEFT(M4,2)="44", RIGHT(M4,LEN(M4)-2),M4) -> 1895238062 | O4: =IFERROR(__xludf.DUMMYFUNCTION("REGEXMATCH(TO_TEXT(N4), ""^07[1-57-9]"")"),FALSE) -> FALSE | P4: =LEN(N4) -> 10 | Q4: =IF(AND(O4=TRUE, P4=11), "✅ VALID", "❌ INVALID") -> ❌ INVALID | R4: UK | S4: 02/24/2022 | T4: =IFERROR(__xludf.DUMMYFUNCTION("IF(ISNUMBER(S4),TEXT(S4,""yyyy-MM-dd""),REGEXREPLACE(REGEXREPLACE(TO_TEXT(S4),""[^0-9a-zA-Z]+"",""-""),""[^0-9]*$"",""""))"),"02-24-2022") -> 02-24-2022 | U4: =TEXT(T4,"yyyy-MM-dd") -> 02-24-2022 | V4: 2022-02-24 | Y4: 2022-02-24
A5: CUST-5003 | B5: ✅ Unique | C5: Vlad Lee | D5: =IFERROR(__xludf.DUMMYFUNCTION("PROPER(REGEXREPLACE(TRIM(C5),""\s+"","" ""))"),"Vlad Lee") -> Vlad Lee | E5: =IFERROR(__xludf.DUMMYFUNCTION("IF(LEN(D5:D701), COUNTA(SPLIT(D5:D701,"" "")), """")"),2.0) -> 2 | F5: =IF(D5=G5,"✅","❌") -> ✅ | G5: =IFERROR(__xludf.DUMMYFUNCTION("REGEXEXTRACT(PROPER(SUBSTITUTE(TRIM(I5),""."","" "")),""^[^@]+"")"),"Vlad Lee") -> Vlad Lee | H5: =LOWER(TRIM(I5)) -> vlad.lee@outlook.com | I5: vlad.lee@outlook.com | J5: =IFERROR(__xludf.DUMMYFUNCTION("IF(REGEXMATCH(TRIM(I5),""^[A-Za-z0-9._%+-]+@[A-Za-z0-9.-]+\.[A-Za-z]{2,}$""),""✅ Valid"",""❌ Invalid"")"),"✅ Valid") -> ✅ Valid | K5: 228-667-113 | L5: =IFERROR(__xludf.DUMMYFUNCTION("IF(OR(K5=""N/A"", K5=""missing"", K5=""none""), """", REGEXREPLACE( SUBSTITUTE(SUBSTITUTE(SUBSTITUTE(TO_TEXT(K5), CHAR(160),""""), UNICHAR(8239),""""), UNICHAR(8201),""""),""[+\-/(): )]"", """"))"),"228667113") -> 228667113 | M5: =IFERROR(__xludf.DUMMYFUNCTION("IF(L5="""","""", REGEXEXTRACT(REGEXREPLACE(L5,""x"", """"), ""[0-9]+""))"),"228667113") -> 228667113 | N5: =IF(LEFT(M5,2)="39", RIGHT(M5,LEN(M5)-2),M5) -> 228667113 | O5: =IFERROR(__xludf.DUMMYFUNCTION("REGEXMATCH(TO_TEXT(N5), ""^3"")"),FALSE) -> FALSE | P5: =LEN(N5) -> 9 | Q5: =IF(AND(O5=TRUE,OR(P5=9, P5=10 )), "✅ VALID", "❌ INVALID") -> ❌ INVALID | R5: Italy | S5: 08.03.2025 | T5: =IFERROR(__xludf.DUMMYFUNCTION("IF(ISNUMBER(S5),TEXT(S5,""yyyy-MM-dd""),REGEXREPLACE(REGEXREPLACE(TO_TEXT(S5),""[^0-9a-zA-Z]+"",""-""),""[^0-9]*$"",""""))"),"08-03-2025") -> 08-03-2025 | U5: 2025-03-08 | Y5: 2025-03-08
A6: CUST-5004 | B6: ✅ Unique | C6: Zack Smith | D6: =IFERROR(__xludf.DUMMYFUNCTION("PROPER(REGEXREPLACE(TRIM(C6),""\s+"","" ""))"),"Zack Smith") -> Zack Smith | E6: =IFERROR(__xludf.DUMMYFUNCTION("IF(LEN(D6:D701), COUNTA(SPLIT(D6:D701,"" "")), """")"),2.0) -> 2 | F6: =IF(D6=G6,"✅","❌") -> ✅ | G6: =IFERROR(__xludf.DUMMYFUNCTION("REGEXEXTRACT(PROPER(SUBSTITUTE(TRIM(I6),""."","" "")),""^[^@]+"")"),"Zack Smith") -> Zack Smith | H6: =LOWER(TRIM(I6)) -> zack.smith@outlookc.om | I6: zack.smith@outlookc.om | J6: =IFERROR(__xludf.DUMMYFUNCTION("IF(REGEXMATCH(TRIM(I6),""^[A-Za-z0-9._%+-]+@[A-Za-z0-9.-]+\.[A-Za-z]{2,}$""),""✅ Valid"",""❌ Invalid"")"),"✅ Valid") -> ✅ Valid | K6: tel:+497822452005 | L6: =IFERROR(__xludf.DUMMYFUNCTION("IF(OR(K6=""N/A"", K6=""missing"", K6=""none""), """", REGEXREPLACE( SUBSTITUTE(SUBSTITUTE(SUBSTITUTE(TO_TEXT(K6), CHAR(160),""""), UNICHAR(8239),""""), UNICHAR(8201),""""),""[+\-/(): )]"", """"))"),"tel497822452005") -> tel497822452005 | M6: =IFERROR(__xludf.DUMMYFUNCTION("IF(L6="""","""", REGEXEXTRACT(REGEXREPLACE(L6,""x"", """"), ""[0-9]+""))"),"497822452005") -> 497822452005 | N6: =IF(LEFT(M6,2)="49", RIGHT(M6,LEN(M6)-2),M6) -> 7822452005 | O6: =IFERROR(__xludf.DUMMYFUNCTION("REGEXMATCH(TO_TEXT(N6), ""^0(15|16|17)"")"),FALSE) -> FALSE | P6: =LEN(N6) -> 10 | Q6: =IF(AND(O6=TRUE,OR(P6=10, P6=11)), "✅ VALID", "❌ INVALID") -> ❌ INVALID | R6: Germany | S6: 44786 | T6: =IFERROR(__xludf.DUMMYFUNCTION("IF(ISNUMBER(S6),TEXT(S6,""yyyy-MM-dd""),REGEXREPLACE(REGEXREPLACE(TO_TEXT(S6),""[^0-9a-zA-Z]+"",""-""),""[^0-9]*$"",""""))"),"2022-08-13") -> 2022-08-13 | U6: 2022-08-13 | Y6: 2022-08-13
A7: CUST-5005 | B7: ✅ Unique | C7: Rita Rodriguez | D7: =IFERROR(__xludf.DUMMYFUNCTION("PROPER(REGEXREPLACE(TRIM(C7),""\s+"","" ""))"),"Rita Rodriguez") -> Rita Rodriguez | E7: =IFERROR(__xludf.DUMMYFUNCTION("IF(LEN(D7:D701), COUNTA(SPLIT(D7:D701,"" "")), """")"),2.0) -> 2 | F7: =IF(D7=G7,"✅","❌") -> ✅ | G7: =IFERROR(__xludf.DUMMYFUNCTION("REGEXEXTRACT(PROPER(SUBSTITUTE(TRIM(I7),""."","" "")),""^[^@]+"")"),"Rita Rodriguez") -> Rita Rodriguez | H7: =LOWER(TRIM(I7)) -> rita.rodriguez@gmail.com | I7: rita.rodriguez@gmail.com | J7: =IFERROR(__xludf.DUMMYFUNCTION("IF(REGEXMATCH(TRIM(I7),""^[A-Za-z0-9._%+-]+@[A-Za-z0-9.-]+\.[A-Za-z]{2,}$""),""✅ Valid"",""❌ Invalid"")"),"✅ Valid") -> ✅ Valid | K7: 9808647248 | L7: =IFERROR(__xludf.DUMMYFUNCTION("IF(OR(K7=""N/A"", K7=""missing"", K7=""none""), """", REGEXREPLACE( SUBSTITUTE(SUBSTITUTE(SUBSTITUTE(TO_TEXT(K7), CHAR(160),""""), UNICHAR(8239),""""), UNICHAR(8201),""""),""[+\-/(): )]"", """"))"),"9808647248") -> 9808647248 | M7: =IFERROR(__xludf.DUMMYFUNCTION("IF(L7="""","""", REGEXEXTRACT(REGEXREPLACE(L7,""x"", """"), ""[0-9]+""))"),"9808647248") -> 9808647248 | N7: =IF(LEFT(M7,1)="1", RIGHT(M7,LEN(M7)-1),M7) -> 9808647248 | O7: =IFERROR(__xludf.DUMMYFUNCTION("REGEXMATCH(TO_TEXT(N7), ""^[2-9][0-9]{9}$"")"),TRUE) -> TRUE | P7: =LEN(N7) -> 10 | Q7: =IF(AND(O7=TRUE, P7=10), "✅ VALID", "❌ INVALID") -> ✅ VALID | R7: USA | S7: 45006 | T7: =IFERROR(__xludf.DUMMYFUNCTION("IF(ISNUMBER(S7),TEXT(S7,""yyyy-MM-dd""),REGEXREPLACE(REGEXREPLACE(TO_TEXT(S7),""[^0-9a-zA-Z]+"",""-""),""[^0-9]*$"",""""))"),"2023-03-21") -> 2023-03-21 | U7: 2023-03-21 | Y7: 2023-03-21
A8: CUST-5006 | B8: ✅ Unique | C8: Gabe Lopze | D8: Gabe Lopez | E8: =IFERROR(__xludf.DUMMYFUNCTION("IF(LEN(D8:D701), COUNTA(SPLIT(D8:D701,"" "")), """")"),2.0) -> 2 | F8: =IF(D8=G8,"✅","❌") -> ✅ | G8: Gabe Lopez | H8: =LOWER(TRIM(I8)) -> gabe.lopez@shop.io | I8: gabe.lopez@shop.io | J8: =IFERROR(__xludf.DUMMYFUNCTION("IF(REGEXMATCH(TRIM(I8),""^[A-Za-z0-9._%+-]+@[A-Za-z0-9.-]+\.[A-Za-z]{2,}$""),""✅ Valid"",""❌ Invalid"")"),"✅ Valid") -> ✅ Valid | K8: +33 045 3496251 | L8: =IFERROR(__xludf.DUMMYFUNCTION("IF(OR(K8=""N/A"", K8=""missing"", K8=""none""), """", REGEXREPLACE( SUBSTITUTE(SUBSTITUTE(SUBSTITUTE(TO_TEXT(K8), CHAR(160),""""), UNICHAR(8239),""""), UNICHAR(8201),""""),""[+\-/(): )]"", """"))"),"330453496251") -> 330453496251 | M8: =IFERROR(__xludf.DUMMYFUNCTION("IF(L8="""","""", REGEXEXTRACT(REGEXREPLACE(L8,""x"", """"), ""[0-9]+""))"),"330453496251") -> 330453496251 | N8: =IF(LEFT(M8,2)="33", RIGHT(M8,LEN(M8)-2),M8) -> 0453496251 | O8: =IFERROR(__xludf.DUMMYFUNCTION("REGEXMATCH(TO_TEXT(N8), ""^0[67]"")"),FALSE) -> FALSE | P8: =LEN(N8) -> 10 | Q8: =IF(AND(O8=TRUE, P8=9), "✅ VALID", "❌ INVALID") -> ❌ INVALID | R8: France | S8: 45652 | T8: =IFERROR(__xludf.DUMMYFUNCTION("IF(ISNUMBER(S8),TEXT(S8,""yyyy-MM-dd""),REGEXREPLACE(REGEXREPLACE(TO_TEXT(S8),""[^0-9a-zA-Z]+"",""-""),""[^0-9]*$"",""""))"),"2024-12-26") -> 2024-12-26 | U8: 2024-12-26 | Y8: 2024-12-26
A9: CUST-5007 | B9: ✅ Unique | C9: Jade Brown | D9: =IFERROR(__xludf.DUMMYFUNCTION("PROPER(REGEXREPLACE(TRIM(C9),""\s+"","" ""))"),"Jade Brown") -> Jade Brown | E9: =IFERROR(__xludf.DUMMYFUNCTION("IF(LEN(D9:D701), COUNTA(SPLIT(D9:D701,"" "")), """")"),2.0) -> 2 | F9: =IF(D9=G9,"✅","❌") -> ❌ | G9: Jad Ebrown | H9: =LOWER(TRIM(I9)) -> jad.ebrown@company.co.uk | I9: JAD.EBROWN@COMPANY.CO.UK | J9: =IFERROR(__xludf.DUMMYFUNCTION("IF(REGEXMATCH(TRIM(I9),""^[A-Za-z0-9._%+-]+@[A-Za-z0-9.-]+\.[A-Za-z]{2,}$""),""✅ Valid"",""❌ Invalid"")"),"✅ Valid") -> ✅ Valid | K9: +35397911194 | L9: =IFERROR(__xludf.DUMMYFUNCTION("IF(OR(K9=""N/A"", K9=""missing"", K9=""none""), """", REGEXREPLACE( SUBSTITUTE(SUBSTITUTE(SUBSTITUTE(TO_TEXT(K9), CHAR(160),""""), UNICHAR(8239),""""), UNICHAR(8201),""""),""[+\-/(): )]"", """"))"),"35397911194") -> 35397911194 | M9: =IFERROR(__xludf.DUMMYFUNCTION("IF(L9="""","""", REGEXEXTRACT(REGEXREPLACE(L9,""x"", """"), ""[0-9]+""))"),"35397911194") -> 35397911194 | N9: =IF(LEFT(M9,3)="353", RIGHT(M9,LEN(M9)-3),M9) -> 97911194 | O9: =IFERROR(__xludf.DUMMYFUNCTION("REGEXMATCH(TO_TEXT(N9), ""^0(83|85|86|87|89)"")"),FALSE) -> FALSE | P9: =LEN(N9) -> 8 | Q9: =IF(AND(O9=TRUE, P6=10), "✅ VALID", "❌ INVALID") -> ❌ INVALID | R9: Ireland | S9: 44932 | T9: =IFERROR(__xludf.DUMMYFUNCTION("IF(ISNUMBER(S9),TEXT(S9,""yyyy-MM-dd""),REGEXREPLACE(REGEXREPLACE(TO_TEXT(S9),""[^0-9a-zA-Z]+"",""-""),""[^0-9]*$"",""""))"),"2023-01-06") -> 2023-01-06 | U9: 2023-01-06 | Y9: 2023-01-06
A10: CUST-5008 | B10: ✅ Unique | C10: Vlad Young | D10: =IFERROR(__xludf.DUMMYFUNCTION("PROPER(REGEXREPLACE(TRIM(C10),""\s+"","" ""))"),"Vlad Young") -> Vlad Young | E10: =IFERROR(__xludf.DUMMYFUNCTION("IF(LEN(D10:D701), COUNTA(SPLIT(D10:D701,"" "")), """")"),2.0) -> 2 | F10: =IF(D10=G10,"✅","❌") -> ✅ | G10: =IFERROR(__xludf.DUMMYFUNCTION("REGEXEXTRACT(PROPER(SUBSTITUTE(TRIM(I10),""."","" "")),""^[^@]+"")"),"Vlad Young") -> Vlad Young | H10: =LOWER(TRIM(I10)) -> vlad.young@example.com | I10: vlad.young@example.com | J10: =IFERROR(__xludf.DUMMYFUNCTION("IF(REGEXMATCH(TRIM(I10),""^[A-Za-z0-9._%+-]+@[A-Za-z0-9.-]+\.[A-Za-z]{2,}$""),""✅ Valid"",""❌ Invalid"")"),"✅ Valid") -> ✅ Valid | K10: (713) 490434 | L10: =IFERROR(__xludf.DUMMYFUNCTION("IF(OR(K10=""N/A"", K10=""missing"", K10=""none""), """", REGEXREPLACE( SUBSTITUTE(SUBSTITUTE(SUBSTITUTE(TO_TEXT(K10), CHAR(160),""""), UNICHAR(8239),""""), UNICHAR(8201),""""),""[+\-/(): )]"", """"))"),"713490434") -> 713490434 | M10: =IFERROR(__xludf.DUMMYFUNCTION("IF(L10="""","""", REGEXEXTRACT(REGEXREPLACE(L10,""x"", """"), ""[0-9]+""))"),"713490434") -> 713490434 | N10: =IF(LEFT(M10,3)="353", RIGHT(M10,LEN(M10)-3),M10) -> 713490434 | O10: =IFERROR(__xludf.DUMMYFUNCTION("REGEXMATCH(TO_TEXT(N10), ""^0(83|85|86|87|89)"")"),FALSE) -> FALSE | P10: =LEN(N10) -> 9 | Q10: =IF(AND(O10=TRUE, P7=10), "✅ VALID", "❌ INVALID") -> ❌ INVALID | R10: Ireland | S10: 44789.78 | T10: =IFERROR(__xludf.DUMMYFUNCTION("IF(ISNUMBER(S10),TEXT(S10,""yyyy-MM-dd""),REGEXREPLACE(REGEXREPLACE(TO_TEXT(S10),""[^0-9a-zA-Z]+"",""-""),""[^0-9]*$"",""""))"),"2022-08-16") -> 2022-08-16 | U10: 2022-08-16 | Y10: 2022-08-16
A11: CUST-5009 | B11: ✅ Unique | C11: Marek Davis | D11: =IFERROR(__xludf.DUMMYFUNCTION("PROPER(REGEXREPLACE(TRIM(C11),""\s+"","" ""))"),"Marek Davis") -> Marek Davis | E11: =IFERROR(__xludf.DUMMYFUNCTION("IF(LEN(D11:D701), COUNTA(SPLIT(D11:D701,"" "")), """")"),2.0) -> 2 | F11: =IF(D11=G11,"✅","❌") -> ✅ | G11: =IFERROR(__xludf.DUMMYFUNCTION("REGEXEXTRACT(PROPER(SUBSTITUTE(TRIM(I11),""."","" "")),""^[^@]+"")"),"Marek Davis") -> Marek Davis | H11: =LOWER(TRIM(I11)) -> marek.davis@gmail.com | I11: marek.davis@gmail.com | J11: =IFERROR(__xludf.DUMMYFUNCTION("IF(REGEXMATCH(TRIM(I11),""^[A-Za-z0-9._%+-]+@[A-Za-z0-9.-]+\.[A-Za-z]{2,}$""),""✅ Valid"",""❌ Invalid"")"),"✅ Valid") -> ✅ Valid | K11: +44-498-57112876 | L11: =IFERROR(__xludf.DUMMYFUNCTION("IF(OR(K11=""N/A"", K11=""missing"", K11=""none""), """", REGEXREPLACE( SUBSTITUTE(SUBSTITUTE(SUBSTITUTE(TO_TEXT(K11), CHAR(160),""""), UNICHAR(8239),""""), UNICHAR(8201),""""),""[+\-/(): )]"", """"))"),"4449857112876") -> 4449857112876 | M11: =IFERROR(__xludf.DUMMYFUNCTION("IF(L11="""","""", REGEXEXTRACT(REGEXREPLACE(L11,""x"", """"), ""[0-9]+""))"),"4449857112876") -> 4449857112876 | N11: =IF(LEFT(M11,2)="44", RIGHT(M11,LEN(M11)-2),M11) -> 49857112876 | O11: =IFERROR(__xludf.DUMMYFUNCTION("REGEXMATCH(TO_TEXT(N11), ""^07[1-57-9]"")"),FALSE) -> FALSE | P11: =LEN(N11) -> 11 | Q11: =IF(AND(O11=TRUE, P11=11), "✅ VALID", "❌ INVALID") -> ❌ INVALID | R11: UK | S11: 45633 | T11: =IFERROR(__xludf.DUMMYFUNCTION("IF(ISNUMBER(S11),TEXT(S11,""yyyy-MM-dd""),REGEXREPLACE(REGEXREPLACE(TO_TEXT(S11),""[^0-9a-zA-Z]+"",""-""),""[^0-9]*$"",""""))"),"2024-12-07") -> 2024-12-07 | U11: 2024-12-07 | Y11: 2024-12-07
A12: CUST-5010 | B12: ✅ Unique | C12: Hanna Kowalski | D12: =IFERROR(__xludf.DUMMYFUNCTION("PROPER(REGEXREPLACE(TRIM(C12),""\s+"","" ""))"),"Hanna Kowalski") -> Hanna Kowalski | E12: =IFERROR(__xludf.DUMMYFUNCTION("IF(LEN(D12:D701), COUNTA(SPLIT(D12:D701,"" "")), """")"),2.0) -> 2 | F12: =IF(D12=G12,"✅","❌") -> ✅ | G12: =IFERROR(__xludf.DUMMYFUNCTION("REGEXEXTRACT(PROPER(SUBSTITUTE(TRIM(I12),""."","" "")),""^[^@]+"")"),"Hanna Kowalski") -> Hanna Kowalski | H12: =LOWER(TRIM(I12)) -> hanna.kowalski@company.co.uk | I12: hanna.kowalski@company.co.uk | J12: =IFERROR(__xludf.DUMMYFUNCTION("IF(REGEXMATCH(TRIM(I12),""^[A-Za-z0-9._%+-]+@[A-Za-z0-9.-]+\.[A-Za-z]{2,}$""),""✅ Valid"",""❌ Invalid"")"),"✅ Valid") -> ✅ Valid | K12: 5x243474533 | L12: =IFERROR(__xludf.DUMMYFUNCTION("IF(OR(K12=""N/A"", K12=""missing"", K12=""none""), """", REGEXREPLACE( SUBSTITUTE(SUBSTITUTE(SUBSTITUTE(TO_TEXT(K12), CHAR(160),""""), UNICHAR(8239),""""), UNICHAR(8201),""""),""[+\-/(): )]"", """"))"),"5x243474533") -> 5x243474533 | M12: =IFERROR(__xludf.DUMMYFUNCTION("IF(L12="""","""", REGEXEXTRACT(REGEXREPLACE(L12,""x"", """"), ""[0-9]+""))"),"5243474533") -> 5243474533 | N12: =IF(LEFT(M12,1)="1", RIGHT(M12,LEN(M12)-1),M12) -> 5243474533 | O12: =IFERROR(__xludf.DUMMYFUNCTION("REGEXMATCH(TO_TEXT(N12), ""^[2-9][0-9]{9}$"")"),TRUE) -> TRUE | P12: =LEN(N12) -> 10 | Q12: =IF(AND(O12=TRUE, P12=10), "✅ VALID", "❌ INVALID") -> ✅ VALID | R12: USA | S12: 45109 | T12: =IFERROR(__xludf.DUMMYFUNCTION("IF(ISNUMBER(S12),TEXT(S12,""yyyy-MM-dd""),REGEXREPLACE(REGEXREPLACE(TO_TEXT(S12),""[^0-9a-zA-Z]+"",""-""),""[^0-9]*$"",""""))"),"2023-07-02") -> 2023-07-02 | U12: 2023-07-02 | Y12: 2023-07-02
A13: CUST-5011 | B13: ✅ Unique | C13: Lia Brown | D13: =IFERROR(__xludf.DUMMYFUNCTION("PROPER(REGEXREPLACE(TRIM(C13),""\s+"","" ""))"),"Lia Brown") -> Lia Brown | E13: =IFERROR(__xludf.DUMMYFUNCTION("IF(LEN(D13:D701), COUNTA(SPLIT(D13:D701,"" "")), """")"),2.0) -> 2 | F13: =IF(D13=G13,"✅","❌") -> ✅ | G13: =IFERROR(__xludf.DUMMYFUNCTION("REGEXEXTRACT(PROPER(SUBSTITUTE(TRIM(I13),""."","" "")),""^[^@]+"")"),"Lia Brown") -> Lia Brown | H13: =LOWER(TRIM(I13)) -> lia.brown@example.com | I13: LIA.BROWN@EXAMPLE.COM | J13: =IFERROR(__xludf.DUMMYFUNCTION("IF(REGEXMATCH(TRIM(I13),""^[A-Za-z0-9._%+-]+@[A-Za-z0-9.-]+\.[A-Za-z]{2,}$""),""✅ Valid"",""❌ Invalid"")"),"✅ Valid") -> ✅ Valid | K13: N/A | L13: =IFERROR(__xludf.DUMMYFUNCTION("IF(OR(K13=""N/A"", K13=""missing"", K13=""none""), """", REGEXREPLACE( SUBSTITUTE(SUBSTITUTE(SUBSTITUTE(TO_TEXT(K13), CHAR(160),""""), UNICHAR(8239),""""), UNICHAR(8201),""""),""[+\-/(): )]"", """"))"),"") | M13: =IFERROR(__xludf.DUMMYFUNCTION("IF(L13="""","""", REGEXEXTRACT(REGEXREPLACE(L13,""x"", """"), ""[0-9]+""))"),"") | N13: =IF(LEFT(M13,2)="33", RIGHT(M13,LEN(M13)-2),M13) | O13: =IFERROR(__xludf.DUMMYFUNCTION("REGEXMATCH(TO_TEXT(N13), ""^0[67]"")"),FALSE) -> FALSE | P13: =LEN(N13) -> 0 | Q13: =IF(AND(O13=TRUE, P13=9), "✅ VALID", "❌ INVALID") -> ❌ INVALID | R13: France | S13: 44794.447 | T13: =IFERROR(__xludf.DUMMYFUNCTION("IF(ISNUMBER(S13),TEXT(S13,""yyyy-MM-dd""),REGEXREPLACE(REGEXREPLACE(TO_TEXT(S13),""[^0-9a-zA-Z]+"",""-""),""[^0-9]*$"",""""))"),"2022-08-21") -> 2022-08-21 | U13: 2022-08-21 | Y13: 2022-08-21
A14: CUST-5012 | B14: ✅ Unique | C14: MAREK DAVIS | D14: =IFERROR(__xludf.DUMMYFUNCTION("PROPER(REGEXREPLACE(TRIM(C14),""\s+"","" ""))"),"Marek Davis") -> Marek Davis | E14: =IFERROR(__xludf.DUMMYFUNCTION("IF(LEN(D14:D701), COUNTA(SPLIT(D14:D701,"" "")), """")"),2.0) -> 2 | F14: =IF(D14=G14,"✅","❌") -> ✅ | G14: =IFERROR(__xludf.DUMMYFUNCTION("REGEXEXTRACT(PROPER(SUBSTITUTE(TRIM(I14),""."","" "")),""^[^@]+"")"),"Marek Davis") -> Marek Davis | H14: =LOWER(TRIM(I14)) -> marek.davis@outlook.com | I14: marek.davis@outlook.com | J14: =IFERROR(__xludf.DUMMYFUNCTION("IF(REGEXMATCH(TRIM(I14),""^[A-Za-z0-9._%+-]+@[A-Za-z0-9.-]+\.[A-Za-z]{2,}$""),""✅ Valid"",""❌ Invalid"")"),"✅ Valid") -> ✅ Valid | K14: +1 899 081892 | L14: =IFERROR(__xludf.DUMMYFUNCTION("IF(OR(K14=""N/A"", K14=""missing"", K14=""none""), """", REGEXREPLACE( SUBSTITUTE(SUBSTITUTE(SUBSTITUTE(TO_TEXT(K14), CHAR(160),""""), UNICHAR(8239),""""), UNICHAR(8201),""""),""[+\-/(): )]"", """"))"),"1899081892") -> 1899081892 | M14: =IFERROR(__xludf.DUMMYFUNCTION("IF(L14="""","""", REGEXEXTRACT(REGEXREPLACE(L14,""x"", """"), ""[0-9]+""))"),"1899081892") -> 1899081892 | N14: =IF(LEFT(M14,1)="1", RIGHT(M14,LEN(M14)-1),M14) -> 899081892 | O14: =IFERROR(__xludf.DUMMYFUNCTION("REGEXMATCH(TO_TEXT(N14), ""^[2-9][0-9]{9}$"")"),FALSE) -> FALSE | P14: =LEN(N14) -> 9 | Q14: =IF(AND(O14=TRUE, P14=10), "✅ VALID", "❌ INVALID") -> ❌ INVALID | R14: USA | S14: 45763 13:29 | T14: =IFERROR(__xludf.DUMMYFUNCTION("IF(ISNUMBER(S14),TEXT(S14,""yyyy-MM-dd""),REGEXREPLACE(REGEXREPLACE(TO_TEXT(S14),""[^0-9a-zA-Z]+"",""-""),""[^0-9]*$"",""""))"),"45763-13-29") -> 45763-13-29 | U14: =TEXT(T14,"yyyy-MM-dd") -> 45763-13-29 | V14: =CONCATENATE(LEFT(U14,5)) -> 45763 | W14: =DATE(1900,1,1) + V14 - 1 -> 45764 | X14: 2025-04-17 | Y14: 2025-04-17
A15: CUST-5013 | B15: ✅ Unique | C15: Lia Lee | D15: =IFERROR(__xludf.DUMMYFUNCTION("PROPER(REGEXREPLACE(TRIM(C15),""\s+"","" ""))"),"Lia Lee") -> Lia Lee | E15: =IFERROR(__xludf.DUMMYFUNCTION("IF(LEN(D15:D701), COUNTA(SPLIT(D15:D701,"" "")), """")"),2.0) -> 2 | F15: =IF(D15=G15,"✅","❌") -> ✅ | G15: =IFERROR(__xludf.DUMMYFUNCTION("REGEXEXTRACT(PROPER(SUBSTITUTE(TRIM(I15),""."","" "")),""^[^@]+"")"),"Lia Lee") -> Lia Lee | H15: =LOWER(TRIM(I15)) -> lia.lee@example.com | I15: lia.lee@example.com | J15: =IFERROR(__xludf.DUMMYFUNCTION("IF(REGEXMATCH(TRIM(I15),""^[A-Za-z0-9._%+-]+@[A-Za-z0-9.-]+\.[A-Za-z]{2,}$""),""✅ Valid"",""❌ Invalid"")"),"✅ Valid") -> ✅ Valid | K15: 734961588 | L15: =IFERROR(__xludf.DUMMYFUNCTION("IF(OR(K15=""N/A"", K15=""missing"", K15=""none""), """", REGEXREPLACE( SUBSTITUTE(SUBSTITUTE(SUBSTITUTE(TO_TEXT(K15), CHAR(160),""""), UNICHAR(8239),""""), UNICHAR(8201),""""),""[+\-/(): )]"", """"))"),"734961588") -> 734961588 | M15: =IFERROR(__xludf.DUMMYFUNCTION("IF(L15="""","""", REGEXEXTRACT(REGEXREPLACE(L15,""x"", """"), ""[0-9]+""))"),"734961588") -> 734961588 | N15: =IF(LEFT(M15,2)="39", RIGHT(M15,LEN(M15)-2),M15) -> 734961588 | O15: =IFERROR(__xludf.DUMMYFUNCTION("REGEXMATCH(TO_TEXT(N15), ""^3"")"),FALSE) -> FALSE | P15: =LEN(N15) -> 9 | Q15: =IF(AND(O15=TRUE,OR(P15=9, P15=10 )), "✅ VALID", "❌ INVALID") -> ❌ INVALID | R15: Italy | S15: 45095 | T15: =IFERROR(__xludf.DUMMYFUNCTION("IF(ISNUMBER(S15),TEXT(S15,""yyyy-MM-dd""),REGEXREPLACE(REGEXREPLACE(TO_TEXT(S15),""[^0-9a-zA-Z]+"",""-""),""[^0-9]*$"",""""))"),"2023-06-18") -> 2023-06-18 | U15: 2023-06-18 | Y15: 2023-06-18
A16: CUST-5014 | B16: ✅ Unique | C16: Lia Young | D16: =IFERROR(__xludf.DUMMYFUNCTION("PROPER(REGEXREPLACE(TRIM(C16),""\s+"","" ""))"),"Lia Young") -> Lia Young | E16: =IFERROR(__xludf.DUMMYFUNCTION("IF(LEN(D16:D701), COUNTA(SPLIT(D16:D701,"" "")), """")"),2.0) -> 2 | F16: =IF(D16=G16,"✅","❌") -> ✅ | G16: =IFERROR(__xludf.DUMMYFUNCTION("REGEXEXTRACT(PROPER(SUBSTITUTE(TRIM(I16),""."","" "")),""^[^@]+"")"),"Lia Young") -> Lia Young | H16: =LOWER(TRIM(I16)) -> lia.young@example.com | I16: lia.young@example.com | J16: =IFERROR(__xludf.DUMMYFUNCTION("IF(REGEXMATCH(TRIM(I16),""^[A-Za-z0-9._%+-]+@[A-Za-z0-9.-]+\.[A-Za-z]{2,}$""),""✅ Valid"",""❌ Invalid"")"),"✅ Valid") -> ✅ Valid | K16: 5519x4599619 | L16: =IFERROR(__xludf.DUMMYFUNCTION("IF(OR(K16=""N/A"", K16=""missing"", K16=""none""), """", REGEXREPLACE( SUBSTITUTE(SUBSTITUTE(SUBSTITUTE(TO_TEXT(K16), CHAR(160),""""), UNICHAR(8239),""""), UNICHAR(8201),""""),""[+\-/(): )]"", """"))"),"5519x4599619") -> 5519x4599619 | M16: =IFERROR(__xludf.DUMMYFUNCTION("IF(L16="""","""", REGEXEXTRACT(REGEXREPLACE(L16,""x"", """"), ""[0-9]+""))"),"55194599619") -> 55194599619 | N16: =IF(LEFT(M16,2)="44", RIGHT(M16,LEN(M16)-2),M16) -> 55194599619 | O16: =IFERROR(__xludf.DUMMYFUNCTION("REGEXMATCH(TO_TEXT(N16), ""^07[1-57-9]"")"),FALSE) -> FALSE | P16: =LEN(N16) -> 11 | Q16: =IF(AND(O16=TRUE, P16=11), "✅ VALID", "❌ INVALID") -> ❌ INVALID | R16: UK | S16: 45496 | T16: =IFERROR(__xludf.DUMMYFUNCTION("IF(ISNUMBER(S16),TEXT(S16,""yyyy-MM-dd""),REGEXREPLACE(REGEXREPLACE(TO_TEXT(S16),""[^0-9a-zA-Z]+"",""-""),""[^0-9]*$"",""""))"),"2024-07-23") -> 2024-07-23 | U16: 2024-07-23 | Y16: 2024-07-23
A17: CUST-5015 | B17: ✅ Unique | C17: Ethan Dubois | D17: =IFERROR(__xludf.DUMMYFUNCTION("PROPER(REGEXREPLACE(TRIM(C17),""\s+"","" ""))"),"Ethan Dubois") -> Ethan Dubois | E17: =IFERROR(__xludf.DUMMYFUNCTION("IF(LEN(D17:D701), COUNTA(SPLIT(D17:D701,"" "")), """")"),2.0) -> 2 | F17: =IF(D17=G17,"✅","❌") -> ✅ | G17: =IFERROR(__xludf.DUMMYFUNCTION("REGEXEXTRACT(PROPER(SUBSTITUTE(TRIM(I17),""."","" "")),""^[^@]+"")"),"Ethan Dubois") -> Ethan Dubois | H17: =LOWER(TRIM(I17)) -> ethan.dubois@yahoo.com | I17: ethan.dubois@yahoo.com | J17: =IFERROR(__xludf.DUMMYFUNCTION("IF(REGEXMATCH(TRIM(I17),""^[A-Za-z0-9._%+-]+@[A-Za-z0-9.-]+\.[A-Za-z]{2,}$""),""✅ Valid"",""❌ Invalid"")"),"✅ Valid") -> ✅ Valid | K17: +34 948 7174624 | L17: =IFERROR(__xludf.DUMMYFUNCTION("IF(OR(K17=""N/A"", K17=""missing"", K17=""none""), """", REGEXREPLACE( SUBSTITUTE(SUBSTITUTE(SUBSTITUTE(TO_TEXT(K17), CHAR(160),""""), UNICHAR(8239),""""), UNICHAR(8201),""""),""[+\-/(): )]"", """"))"),"349487174624") -> 349487174624 | M17: =IFERROR(__xludf.DUMMYFUNCTION("IF(L17="""","""", REGEXEXTRACT(REGEXREPLACE(L17,""x"", """"), ""[0-9]+""))"),"349487174624") -> 349487174624 | N17: =IF(LEFT(M17,2)="34", RIGHT(M17,LEN(M17)-2),M17) -> 9487174624 | O17: =IFERROR(__xludf.DUMMYFUNCTION("REGEXMATCH(TO_TEXT(N17), ""^[67]"")"),FALSE) -> FALSE | P17: =LEN(N17) -> 10 | Q17: =IF(AND(O17=TRUE, P17=9), "✅ VALID", "❌ INVALID") -> ❌ INVALID | R17: Spain | S17: 44809 | T17: =IFERROR(__xludf.DUMMYFUNCTION("IF(ISNUMBER(S17),TEXT(S17,""yyyy-MM-dd""),REGEXREPLACE(REGEXREPLACE(TO_TEXT(S17),""[^0-9a-zA-Z]+"",""-""),""[^0-9]*$"",""""))"),"2022-09-05") -> 2022-09-05 | U17: 2022-09-05 | Y17: 2022-09-05
A18: CUST-5016 | B18: ✅ Unique | C18: Nina Khan | D18: =IFERROR(__xludf.DUMMYFUNCTION("PROPER(REGEXREPLACE(TRIM(C18),""\s+"","" ""))"),"Nina Khan") -> Nina Khan | E18: =IFERROR(__xludf.DUMMYFUNCTION("IF(LEN(D18:D701), COUNTA(SPLIT(D18:D701,"" "")), """")"),2.0) -> 2 | F18: =IF(D18=G18,"✅","❌") -> ✅ | G18: =IFERROR(__xludf.DUMMYFUNCTION("REGEXEXTRACT(PROPER(SUBSTITUTE(TRIM(I18),""."","" "")),""^[^@]+"")"),"Nina Khan") -> Nina Khan | H18: =LOWER(TRIM(I18)) -> nina.khan@example.com | I18: Nina.Khan@Example.Com | J18: =IFERROR(__xludf.DUMMYFUNCTION("IF(REGEXMATCH(TRIM(I18),""^[A-Za-z0-9._%+-]+@[A-Za-z0-9.-]+\.[A-Za-z]{2,}$""),""✅ Valid"",""❌ Invalid"")"),"✅ Valid") -> ✅ Valid | K18: +3920245354 | L18: =IFERROR(__xludf.DUMMYFUNCTION("IF(OR(K18=""N/A"", K18=""missing"", K18=""none""), """", REGEXREPLACE( SUBSTITUTE(SUBSTITUTE(SUBSTITUTE(TO_TEXT(K18), CHAR(160),""""), UNICHAR(8239),""""), UNICHAR(8201),""""),""[+\-/(): )]"", """"))"),"3920245354") -> 3920245354 | M18: =IFERROR(__xludf.DUMMYFUNCTION("IF(L18="""","""", REGEXEXTRACT(REGEXREPLACE(L18,""x"", """"), ""[0-9]+""))"),"3920245354") -> 3920245354 | N18: =IF(LEFT(M18,2)="39", RIGHT(M18,LEN(M18)-2),M18) -> 20245354 | O18: =IFERROR(__xludf.DUMMYFUNCTION("REGEXMATCH(TO_TEXT(N18), ""^3"")"),FALSE) -> FALSE | P18: =LEN(N18) -> 8 | Q18: =IF(AND(O18=TRUE,OR(P18=9, P18=10 )), "✅ VALID", "❌ INVALID") -> ❌ INVALID | R18: Italy | S18: 45844.874 | T18: =IFERROR(__xludf.DUMMYFUNCTION("IF(ISNUMBER(S18),TEXT(S18,""yyyy-MM-dd""),REGEXREPLACE(REGEXREPLACE(TO_TEXT(S18),""[^0-9a-zA-Z]+"",""-""),""[^0-9]*$"",""""))"),"2025-07-06") -> 2025-07-06 | U18: 2025-07-06 | Y18: 2025-07-06
A19: CUST-5017 | B19: ✅ Unique | C19: Rita Lopez | D19: =IFERROR(__xludf.DUMMYFUNCTION("PROPER(REGEXREPLACE(TRIM(C19),""\s+"","" ""))"),"Rita Lopez") -> Rita Lopez | E19: =IFERROR(__xludf.DUMMYFUNCTION("IF(LEN(D19:D701), COUNTA(SPLIT(D19:D701,"" "")), """")"),2.0) -> 2 | F19: =IF(D19=G19,"✅","❌") -> ❌ | G19: Rita Lopze | H19: =LOWER(TRIM(I19)) -> rita.lopze@company.co.uk | I19: RITA.LOPZE@COMPANY.CO.UK | J19: =IFERROR(__xludf.DUMMYFUNCTION("IF(REGEXMATCH(TRIM(I19),""^[A-Za-z0-9._%+-]+@[A-Za-z0-9.-]+\.[A-Za-z]{2,}$""),""✅ Valid"",""❌ Invalid"")"),"✅ Valid") -> ✅ Valid | K19: +353+55796762 | L19: =IFERROR(__xludf.DUMMYFUNCTION("IF(OR(K19=""N/A"", K19=""missing"", K19=""none""), """", REGEXREPLACE( SUBSTITUTE(SUBSTITUTE(SUBSTITUTE(TO_TEXT(K19), CHAR(160),""""), UNICHAR(8239),""""), UNICHAR(8201),""""),""[+\-/(): )]"", """"))"),"35355796762") -> 35355796762 | M19: =IFERROR(__xludf.DUMMYFUNCTION("IF(L19="""","""", REGEXEXTRACT(REGEXREPLACE(L19,""x"", """"), ""[0-9]+""))"),"35355796762") -> 35355796762 | N19: =IF(LEFT(M19,3)="353", RIGHT(M19,LEN(M19)-3),M19) -> 55796762 | O19: =IFERROR(__xludf.DUMMYFUNCTION("REGEXMATCH(TO_TEXT(N19), ""^0(83|85|86|87|89)"")"),FALSE) -> FALSE | P19: =LEN(N19) -> 8 | Q19: =IF(AND(O19=TRUE, P16=10), "✅ VALID", "❌ INVALID") -> ❌ INVALID | R19: Ireland | S19: 45506 | T19: =IFERROR(__xludf.DUMMYFUNCTION("IF(ISNUMBER(S19),TEXT(S19,""yyyy-MM-dd""),REGEXREPLACE(REGEXREPLACE(TO_TEXT(S19),""[^0-9a-zA-Z]+"",""-""),""[^0-9]*$"",""""))"),"2024-08-02") -> 2024-08-02 | U19: 2024-08-02 | Y19: 2024-08-02
A20: CUST-5018 | B20: ✅ Unique | C20: KEN MULLER | D20: =IFERROR(__xludf.DUMMYFUNCTION("PROPER(REGEXREPLACE(TRIM(C20),""\s+"","" ""))"),"Ken Muller") -> Ken Muller | E20: =IFERROR(__xludf.DUMMYFUNCTION("IF(LEN(D20:D701), COUNTA(SPLIT(D20:D701,"" "")), """")"),2.0) -> 2 | F20: =IF(D20=G20,"✅","❌") -> ✅ | G20: =IFERROR(__xludf.DUMMYFUNCTION("REGEXEXTRACT(PROPER(SUBSTITUTE(TRIM(I20),""."","" "")),""^[^@]+"")"),"Ken Muller") -> Ken Muller | H20: =LOWER(TRIM(I20)) -> ken.muller@gmail.com | I20: ken.muller@gmail.com | J20: =IFERROR(__xludf.DUMMYFUNCTION("IF(REGEXMATCH(TRIM(I20),""^[A-Za-z0-9._%+-]+@[A-Za-z0-9.-]+\.[A-Za-z]{2,}$""),""✅ Valid"",""❌ Invalid"")"),"✅ Valid") -> ✅ Valid | K20: +48286084601 | L20: =IFERROR(__xludf.DUMMYFUNCTION("IF(K20=""N/A"", """", REGEXREPLACE( SUBSTITUTE(SUBSTITUTE(SUBSTITUTE(TO_TEXT(K20), CHAR(160),""""), UNICHAR(8239),""""), UNICHAR(8201),""""),""[+\-/(): )]"", """"))"),"48286084601") -> 48286084601 | M20: =IFERROR(__xludf.DUMMYFUNCTION("IF(L20="""","""", REGEXEXTRACT(REGEXREPLACE(L20,""x"", """"), ""[0-9]+""))"),"48286084601") -> 48286084601 | N20: =IF(LEFT(M20,2)="48", RIGHT(M20,LEN(M20)-2),M20) -> 286084601 | O20: =IFERROR(__xludf.DUMMYFUNCTION("REGEXMATCH(TO_TEXT(N20), ""^(5[013679]|6[069]|7[2-9]|88)"")"),FALSE) -> FALSE | Q20: =IF(AND(O20=TRUE, P20=9), "✅ VALID", "❌ INVALID") -> ❌ INVALID | R20: Poland | S20: 44601 | T20: =IFERROR(__xludf.DUMMYFUNCTION("IF(ISNUMBER(S20),TEXT(S20,""yyyy-MM-dd""),REGEXREPLACE(REGEXREPLACE(TO_TEXT(S20),""[^0-9a-zA-Z]+"",""-""),""[^0-9]*$"",""""))"),"2022-02-09") -> 2022-02-09 | U20: 2022-02-09 | Y20: 2022-02-09
A21: CUST-5019 | B21: ✅ Unique | C21: Gabe Khan | D21: =IFERROR(__xludf.DUMMYFUNCTION("PROPER(REGEXREPLACE(TRIM(C21),""\s+"","" ""))"),"Gabe Khan") -> Gabe Khan | E21: =IFERROR(__xludf.DUMMYFUNCTION("IF(LEN(D21:D701), COUNTA(SPLIT(D21:D701,"" "")), """")"),2.0) -> 2 | F21: =IF(D21=G21,"✅","❌") -> ✅ | G21: =IFERROR(__xludf.DUMMYFUNCTION("REGEXEXTRACT(PROPER(SUBSTITUTE(TRIM(I21),""."","" "")),""^[^@]+"")"),"Gabe Khan") -> Gabe Khan | H21: =LOWER(TRIM(I21)) -> gabe.khan@company.co.uk | I21: gabe.khan@company.co.uk | J21: =IFERROR(__xludf.DUMMYFUNCTION("IF(REGEXMATCH(TRIM(I21),""^[A-Za-z0-9._%+-]+@[A-Za-z0-9.-]+\.[A-Za-z]{2,}$""),""✅ Valid"",""❌ Invalid"")"),"✅ Valid") -> ✅ Valid | K21: 759927642 | L21: =IFERROR(__xludf.DUMMYFUNCTION("IF(OR(K21=""N/A"", K21=""missing"", K21=""none""), """", REGEXREPLACE( SUBSTITUTE(SUBSTITUTE(SUBSTITUTE(TO_TEXT(K21), CHAR(160),""""), UNICHAR(8239),""""), UNICHAR(8201),""""),""[+\-/(): )]"", """"))"),"759927642") -> 759927642 | M21: =IFERROR(__xludf.DUMMYFUNCTION("IF(L21="""","""", REGEXEXTRACT(REGEXREPLACE(L21,""x"", """"), ""[0-9]+""))"),"759927642") -> 759927642 | N21: =IF(LEFT(M21,2)="49", RIGHT(M21,LEN(M21)-2),M21) -> 759927642 | O21: =IFERROR(__xludf.DUMMYFUNCTION("REGEXMATCH(TO_TEXT(N21), ""^0(15|16|17)"")"),FALSE) -> FALSE | P21: =LEN(N21) -> 9 | Q21: =IF(AND(O21=TRUE,OR(P21=10, P21=11)), "✅ VALID", "❌ INVALID") -> ❌ INVALID | R21: Germany | S21: 45791 | T21: =IFERROR(__xludf.DUMMYFUNCTION("IF(ISNUMBER(S21),TEXT(S21,""yyyy-MM-dd""),REGEXREPLACE(REGEXREPLACE(TO_TEXT(S21),""[^0-9a-zA-Z]+"",""-""),""[^0-9]*$"",""""))"),"2025-05-14") -> 2025-05-14 | U21: 2025-05-14 | Y21: 2025-05-14
A22: CUST-5020 | B22: ✅ Unique | C22: Xenia Rossi | D22: =IFERROR(__xludf.DUMMYFUNCTION("PROPER(REGEXREPLACE(TRIM(C22),""\s+"","" ""))"),"Xenia Rossi") -> Xenia Rossi | E22: =IFERROR(__xludf.DUMMYFUNCTION("IF(LEN(D22:D701), COUNTA(SPLIT(D22:D701,"" "")), """")"),2.0) -> 2 | F22: =IF(D22=G22,"✅","❌") -> ✅ | G22: =IFERROR(__xludf.DUMMYFUNCTION("REGEXEXTRACT(PROPER(SUBSTITUTE(TRIM(I22),""."","" "")),""^[^@]+"")"),"Xenia Rossi") -> Xenia Rossi | H22: =LOWER(TRIM(I22)) -> xenia.rossi@shop.io | I22: XENIA.ROSSI@SHOP.IO | J22: =IFERROR(__xludf.DUMMYFUNCTION("IF(REGEXMATCH(TRIM(I22),""^[A-Za-z0-9._%+-]+@[A-Za-z0-9.-]+\.[A-Za-z]{2,}$""),""✅ Valid"",""❌ Invalid"")"),"✅ Valid") -> ✅ Valid | K22: 296645265 | L22: =IFERROR(__xludf.DUMMYFUNCTION("IF(OR(K22=""N/A"", K22=""missing"", K22=""none""), """", REGEXREPLACE( SUBSTITUTE(SUBSTITUTE(SUBSTITUTE(TO_TEXT(K22), CHAR(160),""""), UNICHAR(8239),""""), UNICHAR(8201),""""),""[+\-/(): )]"", """"))"),"296645265") -> 296645265 | M22: =IFERROR(__xludf.DUMMYFUNCTION("IF(L22="""","""", REGEXEXTRACT(REGEXREPLACE(L22,""x"", """"), ""[0-9]+""))"),"296645265") -> 296645265 | N22: =IF(LEFT(M22,3)="353", RIGHT(M22,LEN(M22)-3),M22) -> 296645265 | O22: =IFERROR(__xludf.DUMMYFUNCTION("REGEXMATCH(TO_TEXT(N22), ""^0(83|85|86|87|89)"")"),FALSE) -> FALSE | P22: =LEN(N22) -> 9 | Q22: =IF(AND(O22=TRUE, P19=10), "✅ VALID", "❌ INVALID") -> ❌ INVALID | R22: Ireland | S22: 45550 | T22: =IFERROR(__xludf.DUMMYFUNCTION("IF(ISNUMBER(S22),TEXT(S22,""yyyy-MM-dd""),REGEXREPLACE(REGEXREPLACE(TO_TEXT(S22),""[^0-9a-zA-Z]+"",""-""),""[^0-9]*$"",""""))"),"2024-09-15") -> 2024-09-15 | U22: 2024-09-15 | Y22: 2024-09-15
A23: CUST-5021 | B23: ✅ Unique | C23: Uma Brown | D23: =IFERROR(__xludf.DUMMYFUNCTION("PROPER(REGEXREPLACE(TRIM(C23),""\s+"","" ""))"),"Uma Brown") -> Uma Brown | E23: =IFERROR(__xludf.DUMMYFUNCTION("IF(LEN(D23:D701), COUNTA(SPLIT(D23:D701,"" "")), """")"),2.0) -> 2 | F23: =IF(D23=G23,"✅","❌") -> ✅ | G23: =IFERROR(__xludf.DUMMYFUNCTION("REGEXEXTRACT(PROPER(SUBSTITUTE(TRIM(I23),""."","" "")),""^[^@]+"")"),"Uma Brown") -> Uma Brown | H23: =LOWER(TRIM(I23)) -> uma.brown@outlook.com | I23: uma.brown@outlook.com | J23: =IFERROR(__xludf.DUMMYFUNCTION("IF(REGEXMATCH(TRIM(I23),""^[A-Za-z0-9._%+-]+@[A-Za-z0-9.-]+\.[A-Za-z]{2,}$""),""✅ Valid"",""❌ Invalid"")"),"✅ Valid") -> ✅ Valid | K23: missing | L23: =IFERROR(__xludf.DUMMYFUNCTION("IF(OR(K23=""N/A"", K23=""missing"", K23=""none""), """", REGEXREPLACE( SUBSTITUTE(SUBSTITUTE(SUBSTITUTE(TO_TEXT(K23), CHAR(160),""""), UNICHAR(8239),""""), UNICHAR(8201),""""),""[+\-/(): )]"", """"))"),"") | M23: =IFERROR(__xludf.DUMMYFUNCTION("IF(L23="""","""", REGEXEXTRACT(REGEXREPLACE(L23,""x"", """"), ""[0-9]+""))"),"") | N23: =IF(LEFT(M23,2)="39", RIGHT(M23,LEN(M23)-2),M23) | O23: =IFERROR(__xludf.DUMMYFUNCTION("REGEXMATCH(TO_TEXT(N23), ""^3"")"),FALSE) -> FALSE | P23: =LEN(N23) -> 0 | Q23: =IF(AND(O23=TRUE,OR(P23=9, P23=10 )), "✅ VALID", "❌ INVALID") -> ❌ INVALID | R23: Italy | S23: 45446 | T23: =IFERROR(__xludf.DUMMYFUNCTION("IF(ISNUMBER(S23),TEXT(S23,""yyyy-MM-dd""),REGEXREPLACE(REGEXREPLACE(TO_TEXT(S23),""[^0-9a-zA-Z]+"",""-""),""[^0-9]*$"",""""))"),"2024-06-03") -> 2024-06-03 | U23: 2024-06-03 | Y23: 2024-06-03
A24: CUST-5022 | B24: ✅ Unique | C24: Adam Johnson | D24: =IFERROR(__xludf.DUMMYFUNCTION("PROPER(REGEXREPLACE(TRIM(C24),""\s+"","" ""))"),"Adam Johnson") -> Adam Johnson | E24: =IFERROR(__xludf.DUMMYFUNCTION("IF(LEN(D24:D701), COUNTA(SPLIT(D24:D701,"" "")), """")"),2.0) -> 2 | K24: 04528 214 956 | R24: Poland | S24: 24/12/2022
A25: CUST-5023 | B25: ✅ Unique | C25: Jade King | D25: =IFERROR(__xludf.DUMMYFUNCTION("PROPER(REGEXREPLACE(TRIM(C25),""\s+"","" ""))"),"Jade King") -> Jade King | E25: =IFERROR(__xludf.DUMMYFUNCTION("IF(LEN(D25:D701), COUNTA(SPLIT(D25:D701,"" "")), """")"),2.0) -> 2 | F25: =IF(D25=G25,"✅","❌") -> ❌ | G25: Jadek Ing | H25: =LOWER(TRIM(I25)) -> jadek.ing@outlook.com | I25: jadek.ing@outlook.com | J25: =IFERROR(__xludf.DUMMYFUNCTION("IF(REGEXMATCH(TRIM(I25),""^[A-Za-z0-9._%+-]+@[A-Za-z0-9.-]+\.[A-Za-z]{2,}$""),""✅ Valid"",""❌ Invalid"")"),"✅ Valid") -> ✅ Valid | K25: +48-946-661012 | L25: =IFERROR(__xludf.DUMMYFUNCTION("IF(K25=""N/A"", """", REGEXREPLACE( SUBSTITUTE(SUBSTITUTE(SUBSTITUTE(TO_TEXT(K25), CHAR(160),""""), UNICHAR(8239),""""), UNICHAR(8201),""""),""[+\-/(): )]"", """"))"),"48946661012") -> 48946661012 | M25: =IFERROR(__xludf.DUMMYFUNCTION("IF(L25="""","""", REGEXEXTRACT(REGEXREPLACE(L25,""x"", """"), ""[0-9]+""))"),"48946661012") -> 48946661012 | N25: =IF(LEFT(M25,2)="48", RIGHT(M25,LEN(M25)-2),M25) -> 946661012 | O25: =IFERROR(__xludf.DUMMYFUNCTION("REGEXMATCH(TO_TEXT(N25), ""^(5[013679]|6[069]|7[2-9]|88)"")"),FALSE) -> FALSE | Q25: =IF(AND(O25=TRUE, P25=9), "✅ VALID", "❌ INVALID") -> ❌ INVALID | R25: Poland | S25: 45216 | T25: =IFERROR(__xludf.DUMMYFUNCTION("IF(ISNUMBER(S25),TEXT(S25,""yyyy-MM-dd""),REGEXREPLACE(REGEXREPLACE(TO_TEXT(S25),""[^0-9a-zA-Z]+"",""-""),""[^0-9]*$"",""""))"),"2023-10-17") -> 2023-10-17 | U25: 2023-10-17 | Y25: 2023-10-17
A26: CUST-5024 | B26: ✅ Unique | C26: Omar Martinez | D26: =IFERROR(__xludf.DUMMYFUNCTION("PROPER(REGEXREPLACE(TRIM(C26),""\s+"","" ""))"),"Omar Martinez") -> Omar Martinez | E26: =IFERROR(__xludf.DUMMYFUNCTION("IF(LEN(D26:D701), COUNTA(SPLIT(D26:D701,"" "")), """")"),2.0) -> 2 | F26: =IF(D26=G26,"✅","❌") -> ✅ | G26: =IFERROR(__xludf.DUMMYFUNCTION("REGEXEXTRACT(PROPER(SUBSTITUTE(TRIM(I26),""."","" "")),""^[^@]+"")"),"Omar Martinez") -> Omar Martinez | H26: =LOWER(TRIM(I26)) -> omar.martinez@company.co.uk | I26: Omar.Martinez@Company.Co.Uk | J26: =IFERROR(__xludf.DUMMYFUNCTION("IF(REGEXMATCH(TRIM(I26),""^[A-Za-z0-9._%+-]+@[A-Za-z0-9.-]+\.[A-Za-z]{2,}$""),""✅ Valid"",""❌ Invalid"")"),"✅ Valid") -> ✅ Valid | K26: +49-753-01379 | L26: =IFERROR(__xludf.DUMMYFUNCTION("IF(OR(K26=""N/A"", K26=""missing"", K26=""none""), """", REGEXREPLACE( SUBSTITUTE(SUBSTITUTE(SUBSTITUTE(TO_TEXT(K26), CHAR(160),""""), UNICHAR(8239),""""), UNICHAR(8201),""""),""[+\-/(): )]"", """"))"),"4975301379") -> 4975301379 | M26: =IFERROR(__xludf.DUMMYFUNCTION("IF(L26="""","""", REGEXEXTRACT(REGEXREPLACE(L26,""x"", """"), ""[0-9]+""))"),"4975301379") -> 4975301379 | N26: =IF(LEFT(M26,2)="49", RIGHT(M26,LEN(M26)-2),M26) -> 75301379 | O26: =IFERROR(__xludf.DUMMYFUNCTION("REGEXMATCH(TO_TEXT(N26), ""^0(15|16|17)"")"),FALSE) -> FALSE | P26: =LEN(N26) -> 8 | Q26: =IF(AND(O26=TRUE,OR(P26=10, P26=11)), "✅ VALID", "❌ INVALID") -> ❌ INVALID | R26: Germany | S26: 45461 | T26: =IFERROR(__xludf.DUMMYFUNCTION("IF(ISNUMBER(S26),TEXT(S26,""yyyy-MM-dd""),REGEXREPLACE(REGEXREPLACE(TO_TEXT(S26),""[^0-9a-zA-Z]+"",""-""),""[^0-9]*$"",""""))"),"2024-06-18") -> 2024-06-18 | U26: 2024-06-18 | Y26: 2024-06-18
